Workbook
Name LISTE_PERIODES: _xlfn.ANCHORARRAY([1]Listes!$B$2)
Name LISTE_SALARIES: _xlfn.ANCHORARRAY([1]Listes!$A$2)
Name Print_Area: 'ASSI BONAVENTURE'!$A$1:$D$33
Name Print_Area: 'BESONGLACHE PAUL'!$A$1:$D$33
Name Print_Area: 'BLONDE MARCEL'!$A$1:$D$33
Name Print_Area: 'COULIBALY TEMAN'!$A$1:$D$33
Name Print_Area: 'DAN CESAR'!$A$1:$D$33
Name Print_Area: 'ELIE MOUSSA'!$A$1:$D$33
Name Print_Area: 'GNADOU PAULE MARIANNE'!$A$1:$D$33
Name Print_Area: 'KARAMOKO MARCEL'!$A$1:$D$33
Name Print_Area: 'KONAN JEAN YVES'!$A$1:$D$33
Name Print_Area: 'KOUACHY DJOMAN PACOME'!$A$1:$D$33
Name Print_Area: 'OUATTARA ABDOULAYE'!$A$1:$D$33
Name Print_Area: 'SANOGO MORIBA'!$A$1:$D$33
Name Print_Area: 'TANGARA FANTA'!$A$1:$D$33

Sheet Tableau de Bord
A1: TABLEAU DE BORD - PAIE JANVIER 2026
A3: 📊 KPIs PRINCIPAUX | G3: 📊 DONNÉES GRAPHIQUES - COÛT PAR EMPLOYÉ
A4: Effectif total | B4: =COUNTA(Synthèse!A7:A19) -> 13 | D4: Masse salariale brute | E4: =Synthèse!I21 -> 18324875 | G4: Employé | H4: Salaire net | I4: Charges salariales | J4: Charges patronales | K4: Coût total
A5: Salaire brut moyen | B5: =AVERAGE(Synthèse!I7:I19) -> 1409605.8 | D5: Total salaires nets | E5: =Synthèse!K21 -> 13773072 | G5: =Synthèse!A7 -> ELIE MOUSSA | H5: =Synthèse!K7 -> 293528 | I5: =Synthèse!M7+Synthèse!N7+Synthèse!O7 -> 52191 | J5: =Synthèse!Q7+Synthèse!R7+Synthèse!S7+Synthèse!T7+Synthèse!U7+Synthèse!V7+Synthèse!W7+Synthèse!X7+Synthèse!Y7 -> 71259.5 | K5: =H5+I5+J5 -> 416978.5
A6: Salaire brut médian | B6: =MEDIAN(Synthèse!I7:I19) -> 541059 | D6: Total charges salariales | E6: =Synthèse!M21+Synthèse!N21+Synthèse!O21 -> 4941803 | G6: =Synthèse!A8 -> TANGARA FANTA | H6: =Synthèse!K8 -> 2509418 | I6: =Synthèse!M8+Synthèse!N8+Synthèse!O8 -> 1045642 | J6: =Synthèse!Q8+Synthèse!R8+Synthèse!S8+Synthèse!T8+Synthèse!U8+Synthèse!V8+Synthèse!W8+Synthèse!X8+Synthèse!Y8 -> 367639.5 | K6: =H6+I6+J6 -> 3922699.5
A7: Salaire minimum | B7: =MIN(Synthèse!I7:I19) -> 189410 | D7: Total charges patronales | E7: =Synthèse!Q21+Synthèse!R21+Synthèse!S21+Synthèse!T21+Synthèse!U21+Synthèse!V21+Synthèse!W21+Synthèse!X21+Synthèse!Y21 -> 2410517.5 | G7: =Synthèse!A9 -> OUATTARA ABDOULAYE | H7: =Synthèse!K9 -> 257524 | I7: =Synthèse!M9+Synthèse!N9+Synthèse!O9 -> 18499 | J7: =Synthèse!Q9+Synthèse!R9+Synthèse!S9+Synthèse!T9+Synthèse!U9+Synthèse!V9+Synthèse!W9+Synthèse!X9+Synthèse!Y9 -> 36894.5 | K7: =H7+I7+J7 -> 312917.5
A8: Salaire maximum | B8: =MAX(Synthèse!I7:I19) -> 5781400 | D8: Total charges patronales | E8: =Synthèse!Q21+Synthèse!R21+Synthèse!S21+Synthèse!T21+Synthèse!U21+Synthèse!V21+Synthèse!W21+Synthèse!X21+Synthèse!Y21 -> 2410517.5 | G8: =Synthèse!A10 -> KARAMOKO MARCEL | H8: =Synthèse!K10 -> 1338346 | I8: =Synthèse!M10+Synthèse!N10+Synthèse!O10 -> 500615 | J8: =Synthèse!Q10+Synthèse!R10+Synthèse!S10+Synthèse!T10+Synthèse!U10+Synthèse!V10+Synthèse!W10+Synthèse!X10+Synthèse!Y10 -> 198504.5 | K8: =H8+I8+J8 -> 2037465.5
A9: Écart-type salaires | B9: =STDEV(Synthèse!I7:I19) -> 1731980.5 | D9: Ratio net/brut moyen | E9: =E5/E4 -> 0.75160524 | G9: =Synthèse!A11 -> DAN CESAR | H9: =Synthèse!K11 -> 328206 | I9: =Synthèse!M11+Synthèse!N11+Synthèse!O11 -> 51458 | J9: =Synthèse!Q11+Synthèse!R11+Synthèse!S11+Synthèse!T11+Synthèse!U11+Synthèse!V11+Synthèse!W11+Synthèse!X11+Synthèse!Y11 -> 46777.5 | K9: =H9+I9+J9 -> 426441.5
G10: =Synthèse!A12 -> ASSI BONAVENTURE | H10: =Synthèse!K12 -> 208846 | I10: =Synthèse!M12+Synthèse!N12+Synthèse!O12 -> 36529 | J10: =Synthèse!Q12+Synthèse!R12+Synthèse!S12+Synthèse!T12+Synthèse!U12+Synthèse!V12+Synthèse!W12+Synthèse!X12+Synthèse!Y12 -> 31178.5 | K10: =H10+I10+J10 -> 276553.5
A11: 📈 RÉPARTITION DES CHARGES | G11: =Synthèse!A13 -> BESONGACHE PAUL | H11: =Synthèse!K13 -> 4143983 | I11: =Synthèse!M13+Synthèse!N13+Synthèse!O13 -> 1667417 | J11: =Synthèse!Q13+Synthèse!R13+Synthèse!S13+Synthèse!T13+Synthèse!U13+Synthèse!V13+Synthèse!W13+Synthèse!X13+Synthèse!Y13 -> 963706.5 | K11: =H11+I11+J11 -> 6775106.5
A12: Type de charge | B12: Montant | C12: % du total | G12: =Synthèse!A14 -> KONAN JEAN YVES | H12: =Synthèse!K14 -> 738570 | I12: =Synthèse!M14+Synthèse!N14+Synthèse!O14 -> 239880 | J12: =Synthèse!Q14+Synthèse!R14+Synthèse!S14+Synthèse!T14+Synthèse!U14+Synthèse!V14+Synthèse!W14+Synthèse!X14+Synthèse!Y14 -> 108149.5 | K12: =H12+I12+J12 -> 1086599.5
A13: CNPS (Total) | B13: =Synthèse!AA21 -> 2312392.5 | C13: =B13/$B$17 -> 0.31451193 | G13: =Synthèse!A15 -> SANOGO MORIBA | H13: =Synthèse!K15 -> 205477 | I13: =Synthèse!M15+Synthèse!N15+Synthèse!O15 -> 13933 | J13: =Synthèse!Q15+Synthèse!R15+Synthèse!S15+Synthèse!T15+Synthèse!U15+Synthèse!V15+Synthèse!W15+Synthèse!X15+Synthèse!Y15 -> 29951.5 | K13: =H13+I13+J13 -> 249361.5
A14: CMU (Total) | B14: =Synthèse!AB21 -> 35000 | C14: =B14/$B$17 -> 0.0047604018 | G14: =Synthèse!A16 -> COULIBALY TEMAN | H14: =Synthèse!K16 -> 410205 | I14: =Synthèse!M16+Synthèse!N16+Synthèse!O16 -> 110448 | J14: =Synthèse!Q16+Synthèse!R16+Synthèse!S16+Synthèse!T16+Synthèse!U16+Synthèse!V16+Synthèse!W16+Synthèse!X16+Synthèse!Y16 -> 60081.5 | K14: =H14+I14+J14 -> 580734.5
A15: ITS & Taxes (Total) | B15: =Synthèse!AC21 -> 5004928 | C15: =B15/$B$17 -> 0.68072767 | G15: =Synthèse!A17 -> KOUACHY DJOMAN PACOME | H15: =Synthèse!K17 -> 462350 | I15: =Synthèse!M17+Synthèse!N17+Synthèse!O17 -> 108709 | J15: =Synthèse!Q17+Synthèse!R17+Synthèse!S17+Synthèse!T17+Synthèse!U17+Synthèse!V17+Synthèse!W17+Synthèse!X17+Synthèse!Y17 -> 66374.5 | K15: =H15+I15+J15 -> 637433.5
A17: TOTAL CHARGES | B17: =SUM(B13:B15) -> 7352320.5 | C17: =SUM(C13:C15) -> 1 | G17: =Synthèse!A18 -> BLONDE MARCEL | H17: =Synthèse!K18 -> 559523 | I17: =Synthèse!M18+Synthèse!N18+Synthèse!O18 -> 152077 | J17: =Synthèse!Q18+Synthèse!R18+Synthèse!S18+Synthèse!T18+Synthèse!U18+Synthèse!V18+Synthèse!W18+Synthèse!X18+Synthèse!Y18 -> 80629.5 | K17: =H17+I17+J17 -> 792229.5
G18: =Synthèse!A19 -> GNADOU PAULE MARIANNE | H18: =Synthèse!K19 -> 2317096 | I18: =Synthèse!M19+Synthèse!N19+Synthèse!O19 -> 944405 | J18: =Synthèse!Q19+Synthèse!R19+Synthèse!S19+Synthèse!T19+Synthèse!U19+Synthèse!V19+Synthèse!W19+Synthèse!X19+Synthèse!Y19 -> 349370.5 | K18: =H18+I18+J18 -> 3610871.5
A19: 👥 CHARGES SALARIALES vs PATRONALES | G19: TOTAL | H19: =SUM(H5:H18) -> 13773072 | I19: =SUM(I5:I18) -> 4941803 | J19: =SUM(J5:J18) -> 2410517.5 | K19: =SUM(K5:K18) -> 21125392
A20: Catégorie | B20: Montant | C20: % du total
A21: Charges salariales | B21: =Synthèse!M21+Synthèse!N21+Synthèse!O21 -> 4941803 | C21: =B21/(B21+B22) -> 0.67214194 | G21: Employé | H21: Salaire brut
A22: Charges patronales | B22: =E8 -> 2410517.5 | C22: =B22/(B21+B22) -> 0.32785806 | G22: =Synthèse!A7 -> ELIE MOUSSA | H22: =Synthèse!I7 -> 315719
A23: TOTAL | B23: =B21+B22 -> 7352320.5 | C23: =C21+C22 -> 1 | G23: =Synthèse!A8 -> TANGARA FANTA | H23: =Synthèse!I8 -> 3525060
G24: =Synthèse!A9 -> OUATTARA ABDOULAYE | H24: =Synthèse!I9 -> 246023
A25: 🏆 TOP 5 SALAIRES | G25: =Synthèse!A10 -> KARAMOKO MARCEL | H25: =Synthèse!I10 -> 1808961
A26: Rang | B26: Employé | C26: Salaire brut | D26: Salaire net | E26: % masse salariale | G26: =Synthèse!A11 -> DAN CESAR | H26: =Synthèse!I11 -> 349664
A27: 🥇 1 | B27: =INDEX(Synthèse!$A$7:$A$19,MATCH(LARGE(Synthèse!$I$7:$I$19,1),Synthèse!$I$7:$I$19,0)) -> BESONGACHE PAUL | C27: =LARGE(Synthèse!$I$7:$I$19,1) -> 5781400 | D27: =INDEX(Synthèse!$K$7:$K$19,MATCH(C27,Synthèse!$I$7:$I$19,0)) -> 4143983 | E27: =C27/Synthèse!$I$21 -> 0.31549465 | G27: =Synthèse!A12 -> ASSI BONAVENTURE | H27: =Synthèse!I12 -> 215375
A28: 🥈 2 | B28: =INDEX(Synthèse!$A$7:$A$19,MATCH(LARGE(Synthèse!$I$7:$I$19,2),Synthèse!$I$7:$I$19,0)) -> TANGARA FANTA | C28: =LARGE(Synthèse!$I$7:$I$19,2) -> 3525060 | D28: =INDEX(Synthèse!$K$7:$K$19,MATCH(C28,Synthèse!$I$7:$I$19,0)) -> 2509418 | E28: =C28/Synthèse!$I$21 -> 0.19236475 | G28: =Synthèse!A13 -> BESONGACHE PAUL | H28: =Synthèse!I13 -> 5781400
A29: 🥉 3 | B29: =INDEX(Synthèse!$A$7:$A$19,MATCH(LARGE(Synthèse!$I$7:$I$19,3),Synthèse!$I$7:$I$19,0)) -> GNADOU PAULE MARIANNE | C29: =LARGE(Synthèse!$I$7:$I$19,3) -> 3231501 | D29: =INDEX(Synthèse!$K$7:$K$19,MATCH(C29,Synthèse!$I$7:$I$19,0)) -> 2317096 | E29: =C29/Synthèse!$I$21 -> 0.17634505 | G29: =Synthèse!A14 -> KONAN JEAN YVES | H29: =Synthèse!I14 -> 948450
A30: 4 | B30: =INDEX(Synthèse!$A$7:$A$19,MATCH(LARGE(Synthèse!$I$7:$I$19,4),Synthèse!$I$7:$I$19,0)) -> KARAMOKO MARCEL | C30: =LARGE(Synthèse!$I$7:$I$19,4) -> 1808961 | D30: =INDEX(Synthèse!$K$7:$K$19,MATCH(C30,Synthèse!$I$7:$I$19,0)) -> 1338346 | E30: =C30/Synthèse!$I$21 -> 0.098716144 | G30: =Synthèse!A15 -> SANOGO MORIBA | H30: =Synthèse!I15 -> 189410
A31: 5 | B31: =INDEX(Synthèse!$A$7:$A$19,MATCH(LARGE(Synthèse!$I$7:$I$19,5),Synthèse!$I$7:$I$19,0)) -> KONAN JEAN YVES | C31: =LARGE(Synthèse!$I$7:$I$19,5) -> 948450 | D31: =INDEX(Synthèse!$K$7:$K$19,MATCH(C31,Synthèse!$I$7:$I$19,0)) -> 738570 | E31: =C31/Synthèse!$I$21 -> 0.051757515 | G31: =Synthèse!A16 -> COULIBALY TEMAN | H31: =Synthèse!I16 -> 490653
G32: =Synthèse!A17 -> KOUACHY DJOMAN PACOME | H32: =Synthèse!I17 -> 541059
A33: ⚠️ ALERTES & INDICATEURS
A34: Indicateur | B34: Valeur | C34: Statut | G34: =Synthèse!A18 -> BLONDE MARCEL | H34: =Synthèse!I18 -> 681600
A35: Employés ITS = 0 (exonérés) | B35: =COUNTIF(Synthèse!O7:O19,0) -> 2 | C35: =IF(B35>0,"🟡 "&B35&" employé(s)","🟢 Aucun") -> 🟡 2 employé(s) | G35: =Synthèse!A19 -> GNADOU PAULE MARIANNE | H35: =Synthèse!I19 -> 3231501
A36: % charges / masse salariale brute | B36: =B17/E4 -> 0.40122077 | C36: =IF(B36>0.5,"🔴 Très élevé",IF(B36>0.4,"🟡 Élevé","🟢 Normal")) -> 🟡 Élevé
A37: Top 5 = % de la masse salariale | B37: =SUM(E27:E31) -> 0.83467811 | C37: =IF(B37>0.8,"🔴 Très concentré",IF(B37>0.6,"🟡 Concentré","🟢 Équilibré")) -> 🔴 Très concentré
A39: 📊 RATIOS CLÉS
A40: Ratio | B40: Valeur | C40: Interprétation
A41: Charges patronales / Masse salariale | B41: =E8/E4 -> 0.13154346 | C41: Coût supplémentaire employeur
A42: Salaire net moyen / Salaire brut moyen | B42: =AVERAGE(Synthèse!K7:K19)/AVERAGE(Synthèse!I7:I19) -> 0.75160524 | C42: Taux de rétention du salaire
A43: Coût moyen par employé (total) | B43: =E9/B4 -> 0.057815787 | C43: Incluant toutes les charges
...

Sheet Synthèse
A1: ="Charges sociales et fiscales "&PROPER(TEXT($I$1,"mmmm aaaa")) -> Charges sociales et fiscales Février 2026 | I1: 46081
M3: Charges sociales et fiscales salariales | Q3: Charges sociales et fiscales patronales
A5: Salariés | B5: Matricule | C5: Compte SAGE | D5: Local | E5: Situation | F5: Nb Enfants | G5: Parts | I5: Salaire brut | J5: Transport | K5: Salaire net | M5: Caisse de retraite | N5: CMU Salarié | O5: ITS Salarié | Q5: Caisse de retraite | R5: Assurance Maternité | S5: Prestations familiales | T5: Accident de travail | U5: CMU Employeur | V5: Contribution Employeur | W5: Contribution Nationale | X5: Taxe d'apprentissage | Y5: FDFP | AA5: Total CNPS | AB5: Total CMU | AC5: Total ITS
A7: ='ELIE MOUSSA'!$B$3 -> ELIE MOUSSA | B7: 11318 | C7: SAL0001 | D7: ='ELIE MOUSSA'!$B$5 -> Non | E7: ='ELIE MOUSSA'!$B$6 -> M | F7: ='ELIE MOUSSA'!$B$7 -> 0 | G7: ='ELIE MOUSSA'!$B$8 -> 2 | I7: ='ELIE MOUSSA'!$C$14 -> 315719 | J7: ='ELIE MOUSSA'!$C$30 -> 30000 | K7: ='ELIE MOUSSA'!$C$31 -> 293528 | M7: ='ELIE MOUSSA'!$C$23 -> 19890 | N7: ='ELIE MOUSSA'!$C$28 -> 1000 | O7: ='ELIE MOUSSA'!$C$17 -> 31301 | Q7: ='ELIE MOUSSA'!$D$24 -> 24310 | R7: ='ELIE MOUSSA'!$D$26 -> 562.5 | S7: ='ELIE MOUSSA'!$D$25 -> 3750 | T7: ='ELIE MOUSSA'!$D$27 -> 3750 | U7: ='ELIE MOUSSA'!$D$29 -> 1000 | V7: ='ELIE MOUSSA'!$D$18 -> 29046 | W7: ='ELIE MOUSSA'!$D$19 -> 3789 | X7: ='ELIE MOUSSA'!$D$20 -> 1263 | Y7: ='ELIE MOUSSA'!$D$21 -> 3789 | AA7: =M7+Q7+R7+S7+T7 -> 52262.5 | AB7: =N7+U7 -> 2000 | AC7: =O7+V7+W7+X7+Y7 -> 69188
A8: ='TANGARA FANTA'!$B$3 -> TANGARA FANTA | B8: 11677 | C8: SAL0003 | D8: ='TANGARA FANTA'!$B$5 -> Oui | E8: ='TANGARA FANTA'!$B$6 -> M | F8: ='TANGARA FANTA'!$B$7 -> 0 | G8: ='TANGARA FANTA'!$B$8 -> 2 | I8: ='TANGARA FANTA'!$C$14 -> 3525060 | J8: ='TANGARA FANTA'!$C$30 -> 30000 | K8: ='TANGARA FANTA'!$C$31 -> 2509418 | M8: ='TANGARA FANTA'!$C$23 -> 212625 | N8: ='TANGARA FANTA'!$C$28 -> 1000 | O8: ='TANGARA FANTA'!$C$17 -> 832017 | Q8: ='TANGARA FANTA'!$D$24 -> 259875 | R8: ='TANGARA FANTA'!$D$26 -> 562.5 | S8: ='TANGARA FANTA'!$D$25 -> 3750 | T8: ='TANGARA FANTA'!$D$27 -> 3750 | U8: ='TANGARA FANTA'!$D$29 -> 1000 | V8: ='TANGARA FANTA'!$D$18 -> 0 | W8: ='TANGARA FANTA'!$D$19 -> 42301 | X8: ='TANGARA FANTA'!$D$20 -> 14100 | Y8: ='TANGARA FANTA'!$D$21 -> 42301 | AA8: =M8+Q8+R8+S8+T8 -> 480562.5 | AB8: =N8+U8 -> 2000 | AC8: =O8+V8+W8+X8+Y8 -> 930719
A9: ='OUATTARA ABDOULAYE'!$B$3 -> OUATTARA ABDOULAYE | B9: 11956 | C9: SAL0002 | D9: ='OUATTARA ABDOULAYE'!$B$5 -> Oui | E9: ='OUATTARA ABDOULAYE'!$B$6 -> M | F9: ='OUATTARA ABDOULAYE'!$B$7 -> 4 | G9: ='OUATTARA ABDOULAYE'!$B$8 -> 4 | I9: ='OUATTARA ABDOULAYE'!$C$14 -> 246023 | J9: ='OUATTARA ABDOULAYE'!$C$30 -> 30000 | K9: ='OUATTARA ABDOULAYE'!$C$31 -> 257524 | M9: ='OUATTARA ABDOULAYE'!$C$23 -> 15499 | N9: ='OUATTARA ABDOULAYE'!$C$28 -> 3000 | O9: ='OUATTARA ABDOULAYE'!$C$17 -> 0 | Q9: ='OUATTARA ABDOULAYE'!$D$24 -> 18944 | R9: ='OUATTARA ABDOULAYE'!$D$26 -> 562.5 | S9: ='OUATTARA ABDOULAYE'!$D$25 -> 3750 | T9: ='OUATTARA ABDOULAYE'!$D$27 -> 3750 | U9: ='OUATTARA ABDOULAYE'!$D$29 -> 3000 | V9: ='OUATTARA ABDOULAYE'!$D$18 -> 0 | W9: ='OUATTARA ABDOULAYE'!$D$19 -> 2952 | X9: ='OUATTARA ABDOULAYE'!$D$20 -> 984 | Y9: ='OUATTARA ABDOULAYE'!$D$21 -> 2952 | AA9: =M9+Q9+R9+S9+T9 -> 42505.5 | AB9: =N9+U9 -> 6000 | AC9: =O9+V9+W9+X9+Y9 -> 6888
A10: ='KARAMOKO MARCEL'!$B$3 -> KARAMOKO MARCEL | B10: 12577 | C10: SAL0004 | D10: ='KARAMOKO MARCEL'!$B$5 -> Oui | E10: ='KARAMOKO MARCEL'!$B$6 -> C | F10: ='KARAMOKO MARCEL'!$B$7 -> 0 | G10: ='KARAMOKO MARCEL'!$B$8 -> 1 | I10: ='KARAMOKO MARCEL'!$C$14 -> 1808961 | J10: ='KARAMOKO MARCEL'!$C$30 -> 30000 | K10: ='KARAMOKO MARCEL'!$C$31 -> 1338346 | M10: ='KARAMOKO MARCEL'!$C$23 -> 113965 | N10: ='KARAMOKO MARCEL'!$C$28 -> 500 | O10: ='KARAMOKO MARCEL'!$C$17 -> 386150 | Q10: ='KARAMOKO MARCEL'!$D$24 -> 139290 | R10: ='KARAMOKO MARCEL'!$D$26 -> 562.5 | S10: ='KARAMOKO MARCEL'!$D$25 -> 3750 | T10: ='KARAMOKO MARCEL'!$D$27 -> 3750 | U10: ='KARAMOKO MARCEL'!$D$29 -> 500 | V10: ='KARAMOKO MARCEL'!$D$18 -> 0 | W10: ='KARAMOKO MARCEL'!$D$19 -> 21708 | X10: ='KARAMOKO MARCEL'!$D$20 -> 7236 | Y10: ='KARAMOKO MARCEL'!$D$21 -> 21708 | AA10: =M10+Q10+R10+S10+T10 -> 261317.5 | AB10: =N10+U10 -> 1000 | AC10: =O10+V10+W10+X10+Y10 -> 436802
A11: ='DAN CESAR'!$B$3 -> DAN CESAR | B11: 12760 | C11: SAL0007 | D11: ='DAN CESAR'!$B$5 -> Oui | E11: ='DAN CESAR'!$B$6 -> M | F11: ='DAN CESAR'!$B$7 -> 2 | G11: ='DAN CESAR'!$B$8 -> 3 | I11: ='DAN CESAR'!$C$14 -> 349664 | J11: ='DAN CESAR'!$C$30 -> 30000 | K11: ='DAN CESAR'!$C$31 -> 328206 | M11: ='DAN CESAR'!$C$23 -> 22029 | N11: ='DAN CESAR'!$C$28 -> 2000 | O11: ='DAN CESAR'!$C$17 -> 27429 | Q11: ='DAN CESAR'!$D$24 -> 26924 | R11: ='DAN CESAR'!$D$26 -> 562.5 | S11: ='DAN CESAR'!$D$25 -> 3750 | T11: ='DAN CESAR'!$D$27 -> 3750 | U11: ='DAN CESAR'!$D$29 -> 2000 | V11: ='DAN CESAR'!$D$18 -> 0 | W11: ='DAN CESAR'!$D$19 -> 4196 | X11: ='DAN CESAR'!$D$20 -> 1399 | Y11: ='DAN CESAR'!$D$21 -> 4196 | AA11: =M11+Q11+R11+S11+T11 -> 57015.5 | AB11: =N11+U11 -> 4000 | AC11: =O11+V11+W11+X11+Y11 -> 37220
A12: ='ASSI BONAVENTURE'!$B$3 -> ASSI BONAVENTURE | B12: 12820 | C12: SAL0008 | D12: ='ASSI BONAVENTURE'!$B$5 -> Oui | E12: ='ASSI BONAVENTURE'!$B$6 -> C | F12: ='ASSI BONAVENTURE'!$B$7 -> 0 | G12: ='ASSI BONAVENTURE'!$B$8 -> 1 | I12: ='ASSI BONAVENTURE'!$C$14 -> 215375 | J12: ='ASSI BONAVENTURE'!$C$30 -> 30000 | K12: ='ASSI BONAVENTURE'!$C$31 -> 208846 | M12: ='ASSI BONAVENTURE'!$C$23 -> 13569 | N12: ='ASSI BONAVENTURE'!$C$28 -> 500 | O12: ='ASSI BONAVENTURE'!$C$17 -> 22460 | Q12: ='ASSI BONAVENTURE'!$D$24 -> 16584 | R12: ='ASSI BONAVENTURE'!$D$26 -> 562.5 | S12: ='ASSI BONAVENTURE'!$D$25 -> 3750 | T12: ='ASSI BONAVENTURE'!$D$27 -> 3750 | U12: ='ASSI BONAVENTURE'!$D$29 -> 500 | V12: ='ASSI BONAVENTURE'!$D$18 -> 0 | W12: ='ASSI BONAVENTURE'!$D$19 -> 2585 | X12: ='ASSI BONAVENTURE'!$D$20 -> 862 | Y12: ='ASSI BONAVENTURE'!$D$21 -> 2585 | AA12: =M12+Q12+R12+S12+T12 -> 38215.5 | AB12: =N12+U12 -> 1000 | AC12: =O12+V12+W12+X12+Y12 -> 28492
A13: ='BESONGLACHE PAUL'!$B$3 -> BESONGACHE PAUL | B13: 12834 | C13: SAL0010 | D13: ='BESONGLACHE PAUL'!$B$5 -> Non | E13: ='BESONGLACHE PAUL'!$B$6 -> M | F13: ='BESONGLACHE PAUL'!$B$7 -> 2 | G13: ='BESONGLACHE PAUL'!$B$8 -> 3 | I13: ='BESONGLACHE PAUL'!$C$14 -> 5781400 | J13: ='BESONGLACHE PAUL'!$C$30 -> 30000 | K13: ='BESONGLACHE PAUL'!$C$31 -> 4143983 | M13: ='BESONGLACHE PAUL'!$C$23 -> 212625 | N13: ='BESONGLACHE PAUL'!$C$28 -> 2000 | O13: ='BESONGLACHE PAUL'!$C$17 -> 1452792 | Q13: ='BESONGLACHE PAUL'!$D$24 -> 259875 | R13: ='BESONGLACHE PAUL'!$D$26 -> 562.5 | S13: ='BESONGLACHE PAUL'!$D$25 -> 3750 | T13: ='BESONGLACHE PAUL'!$D$27 -> 3750 | U13: ='BESONGLACHE PAUL'!$D$29 -> 2000 | V13: ='BESONGLACHE PAUL'!$D$18 -> 531889 | W13: ='BESONGLACHE PAUL'!$D$19 -> 69377 | X13: ='BESONGLACHE PAUL'!$D$20 -> 23126 | Y13: ='BESONGLACHE PAUL'!$D$21 -> 69377 | AA13: =M13+Q13+R13+S13+T13 -> 480562.5 | AB13: =N13+U13 -> 4000 | AC13: =O13+V13+W13+X13+Y13 -> 2146561
A14: ='KONAN JEAN YVES'!$B$3 -> KONAN JEAN YVES | B14: 12842 | C14: SAL0012 | D14: ='KONAN JEAN YVES'!$B$5 -> Oui | E14: ='KONAN JEAN YVES'!$B$6 -> C | F14: ='KONAN JEAN YVES'!$B$7 -> 0 | G14: ='KONAN JEAN YVES'!$B$8 -> 1 | I14: ='KONAN JEAN YVES'!$C$14 -> 948450 | J14: ='KONAN JEAN YVES'!$C$30 -> 30000 | K14: ='KONAN JEAN YVES'!$C$31 -> 738570 | M14: ='KONAN JEAN YVES'!$C$23 -> 59752 | N14: ='KONAN JEAN YVES'!$C$28 -> 500 | O14: ='KONAN JEAN YVES'!$C$17 -> 179628 | Q14: ='KONAN JEAN YVES'!$D$24 -> 73031 | R14: ='KONAN JEAN YVES'!$D$26 -> 562.5 | S14: ='KONAN JEAN YVES'!$D$25 -> 3750 | T14: ='KONAN JEAN YVES'!$D$27 -> 3750 | U14: ='KONAN JEAN YVES'!$D$29 -> 500 | V14: ='KONAN JEAN YVES'!$D$18 -> 0 | W14: ='KONAN JEAN YVES'!$D$19 -> 11381 | X14: ='KONAN JEAN YVES'!$D$20 -> 3794 | Y14: ='KONAN JEAN YVES'!$D$21 -> 11381 | AA14: =M14+Q14+R14+S14+T14 -> 140845.5 | AB14: =N14+U14 -> 1000 | AC14: =O14+V14+W14+X14+Y14 -> 206184
A15: ='SANOGO MORIBA'!$B$3 -> SANOGO MORIBA | B15: 12850 | C15: SAL0013 | D15: ='SANOGO MORIBA'!$B$5 -> Oui | E15: ='SANOGO MORIBA'!$B$6 -> C | F15: ='SANOGO MORIBA'!$B$7 -> 3 | G15: ='SANOGO MORIBA'!$B$8 -> 3 | I15: ='SANOGO MORIBA'!$C$14 -> 189410 | J15: ='SANOGO MORIBA'!$C$30 -> 30000 | K15: ='SANOGO MORIBA'!$C$31 -> 205477 | M15: ='SANOGO MORIBA'!$C$23 -> 11933 | N15: ='SANOGO MORIBA'!$C$28 -> 2000 | O15: ='SANOGO MORIBA'!$C$17 -> 0 | Q15: ='SANOGO MORIBA'!$D$24 -> 14585 | R15: ='SANOGO MORIBA'!$D$26 -> 562.5 | S15: ='SANOGO MORIBA'!$D$25 -> 3750 | T15: ='SANOGO MORIBA'!$D$27 -> 3750 | U15: ='SANOGO MORIBA'!$D$29 -> 2000 | V15: ='SANOGO MORIBA'!$D$18 -> 0 | W15: ='SANOGO MORIBA'!$D$19 -> 2273 | X15: ='SANOGO MORIBA'!$D$20 -> 758 | Y15: ='SANOGO MORIBA'!$D$21 -> 2273 | AA15: =M15+Q15+R15+S15+T15 -> 34580.5 | AB15: =N15+U15 -> 4000 | AC15: =O15+V15+W15+X15+Y15 -> 5304
A16: ='COULIBALY TEMAN'!$B$3 -> COULIBALY TEMAN | B16: 12852 | C16: SAL0014 | D16: ='COULIBALY TEMAN'!$B$5 -> Oui | E16: ='COULIBALY TEMAN'!$B$6 -> C | F16: ='COULIBALY TEMAN'!$B$7 -> 0 | G16: ='COULIBALY TEMAN'!$B$8 -> 1 | I16: ='COULIBALY TEMAN'!$C$14 -> 490653 | J16: ='COULIBALY TEMAN'!$C$30 -> 30000 | K16: ='COULIBALY TEMAN'!$C$31 -> 410205 | M16: ='COULIBALY TEMAN'!$C$23 -> 30911 | N16: ='COULIBALY TEMAN'!$C$28 -> 500 | O16: ='COULIBALY TEMAN'!$C$17 -> 79037 | Q16: ='COULIBALY TEMAN'!$D$24 -> 37780 | R16: ='COULIBALY TEMAN'!$D$26 -> 562.5 | S16: ='COULIBALY TEMAN'!$D$25 -> 3750 | T16: ='COULIBALY TEMAN'!$D$27 -> 3750 | U16: ='COULIBALY TEMAN'!$D$29 -> 500 | V16: ='COULIBALY TEMAN'!$D$18 -> 0 | W16: ='COULIBALY TEMAN'!$D$19 -> 5888 | X16: ='COULIBALY TEMAN'!$D$20 -> 1963 | Y16: ='COULIBALY TEMAN'!$D$21 -> 5888 | AA16: =M16+Q16+R16+S16+T16 -> 76753.5 | AB16: =N16+U16 -> 1000 | AC16: =O16+V16+W16+X16+Y16 -> 92776
A17: ='KOUACHY DJOMAN PACOME'!$B$3 -> KOUACHY DJOMAN PACOME | B17: 12853 | C17: SAL0015 | D17: ='KOUACHY DJOMAN PACOME'!$B$5 -> Oui | E17: ='KOUACHY DJOMAN PACOME'!$B$6 -> C | F17: ='KOUACHY DJOMAN PACOME'!$B$7 -> 2 | G17: ='KOUACHY DJOMAN PACOME'!$B$8 -> 2.5 | I17: ='KOUACHY DJOMAN PACOME'!$C$14 -> 541059 | J17: ='KOUACHY DJOMAN PACOME'!$C$30 -> 30000 | K17: ='KOUACHY DJOMAN PACOME'!$C$31 -> 462350 | M17: ='KOUACHY DJOMAN PACOME'!$C$23 -> 34087 | N17: ='KOUACHY DJOMAN PACOME'!$C$28 -> 1500 | O17: ='KOUACHY DJOMAN PACOME'!$C$17 -> 73122 | Q17: ='KOUACHY DJOMAN PACOME'!$D$24 -> 41662 | R17: ='KOUACHY DJOMAN PACOME'!$D$26 -> 562.5 | S17: ='KOUACHY DJOMAN PACOME'!$D$25 -> 3750 | T17: ='KOUACHY DJOMAN PACOME'!$D$27 -> 3750 | U17: ='KOUACHY DJOMAN PACOME'!$D$29 -> 1500 | V17: ='KOUACHY DJOMAN PACOME'!$D$18 -> 0 | W17: ='KOUACHY DJOMAN PACOME'!$D$19 -> 6493 | X17: ='KOUACHY DJOMAN PACOME'!$D$20 -> 2164 | Y17: ='KOUACHY DJOMAN PACOME'!$D$21 -> 6493 | AA17: =M17+Q17+R17+S17+T17 -> 83811.5 | AB17: =N17+U17 -> 3000 | AC17: =O17+V17+W17+X17+Y17 -> 88272
A18: ='BLONDE MARCEL'!$B$3 -> BLONDE MARCEL | B18: 12855 | C18: SAL0017 | D18: ='BLONDE MARCEL'!$B$5 -> Oui | E18: ='BLONDE MARCEL'!$B$6 -> M | F18: ='BLONDE MARCEL'!$B$7 -> 0 | G18: ='BLONDE MARCEL'!$B$8 -> 2 | I18: ='BLONDE MARCEL'!$C$14 -> 681600 | J18: ='BLONDE MARCEL'!$C$30 -> 30000 | K18: ='BLONDE MARCEL'!$C$31 -> 559523 | M18: ='BLONDE MARCEL'!$C$23 -> 42941 | N18: ='BLONDE MARCEL'!$C$28 -> 1000 | O18: ='BLONDE MARCEL'!$C$17 -> 108136 | Q18: ='BLONDE MARCEL'!$D$24 -> 52483 | R18: ='BLONDE MARCEL'!$D$26 -> 562.5 | S18: ='BLONDE MARCEL'!$D$25 -> 3750 | T18: ='BLONDE MARCEL'!$D$27 -> 3750 | U18: ='BLONDE MARCEL'!$D$29 -> 1000 | V18: ='BLONDE MARCEL'!$D$18 -> 0 | W18: ='BLONDE MARCEL'!$D$19 -> 8179 | X18: ='BLONDE MARCEL'!$D$20 -> 2726 | Y18: ='BLONDE MARCEL'!$D$21 -> 8179 | AA18: =M18+Q18+R18+S18+T18 -> 103486.5 | AB18: =N18+U18 -> 2000 | AC18: =O18+V18+W18+X18+Y18 -> 127220
A19: ='GNADOU PAULE MARIANNE'!$B$3 -> GNADOU PAULE MARIANNE | B19: 12863 | C19: SAL0018 | D19: ='GNADOU PAULE MARIANNE'!$B$5 -> Oui | E19: ='GNADOU PAULE MARIANNE'!$B$6 -> C | F19: ='GNADOU PAULE MARIANNE'!$B$7 -> 3 | G19: ='GNADOU PAULE MARIANNE'!$B$8 -> 3 | I19: ='GNADOU PAULE MARIANNE'!$C$14 -> 3231501 | J19: ='GNADOU PAULE MARIANNE'!$C$30 -> 30000 | K19: ='GNADOU PAULE MARIANNE'!$C$31 -> 2317096 | M19: ='GNADOU PAULE MARIANNE'!$C$23 -> 203585 | N19: ='GNADOU PAULE MARIANNE'!$C$28 -> 2000 | O19: ='GNADOU PAULE MARIANNE'!$C$17 -> 738820 | Q19: ='GNADOU PAULE MARIANNE'!$D$24 -> 248826 | R19: ='GNADOU PAULE MARIANNE'!$D$26 -> 562.5 | S19: ='GNADOU PAULE MARIANNE'!$D$25 -> 3750 | T19: ='GNADOU PAULE MARIANNE'!$D$27 -> 3750 | U19: ='GNADOU PAULE MARIANNE'!$D$29 -> 2000 | V19: ='GNADOU PAULE MARIANNE'!$D$18 -> 0 | W19: ='GNADOU PAULE MARIANNE'!$D$19 -> 38778 | X19: ='GNADOU PAULE MARIANNE'!$D$20 -> 12926 | Y19: ='GNADOU PAULE MARIANNE'!$D$21 -> 38778 | AA19: =M19+Q19+R19+S19+T19 -> 460473.5 | AB19: =N19+U19 -> 4000 | AC19: =O19+V19+W19+X19+Y19 -> 829302
A21: TOTAUX | I21: =SUM(I7:I19) -> 18324875 | J21: =SUM(J7:J19) -> 390000 | K21: =SUM(K7:K19) -> 13773072 | M21: =SUM(M7:M19) -> 993411 | N21: =SUM(N7:N19) -> 17500 | O21: =SUM(O7:O19) -> 3930892 | Q21: =SUM(Q7:Q19) -> 1214169 | R21: =SUM(R7:R19) -> 7312.5 | S21: =SUM(S7:S19) -> 48750 | T21: =SUM(T7:T19) -> 48750 | U21: =SUM(U7:U19) -> 17500 | V21: =SUM(V7:V19) -> 560935 | W21: =SUM(W7:W19) -> 219900 | X21: =SUM(X7:X19) -> 73301 | Y21: =SUM(Y7:Y19) -> 219900 | AA21: =SUM(AA7:AA19) -> 2312392.5 | AB21: =SUM(AB7:AB19) -> 35000 | AC21: =SUM(AC7:AC19) -> 5004928

Sheet Comptabilisation
A1: ="Comptabilisation charges sociales et fiscales "&PROPER(TEXT(Synthèse!$I$1,"mmmm aaaa")) -> Comptabilisation charges sociales et fiscales Février 2026 | Q1: Synthèse
A3: ="Comptabilisation charges salariales "&PROPER(TEXT(Synthèse!$I$1,"mmmm aaaa")) -> Comptabilisation charges salariales Février 2026 | J3: ="Comptabilisation charges patronales "&PROPER(TEXT(Synthèse!$I$1,"mmmm aaaa")) -> Comptabilisation charges patronales Février 2026
A5: Date | B5: Journal | C5: Compte | D5: Tiers | E5: Libellé | F5: Débit | G5: Crédit | J5: Date | K5: Journal | L5: Compte | M5: Tiers | N5: Libellé | O5: Débit | P5: Crédit
A6: =Synthèse!$I$1 -> 46081 | B6: SAL | C6: 6611000 | E6: ="Salaires bruts "&PROPER(TEXT($A6,"mmm aaaa")) -> Salaires bruts Févr 2026 | F6: =Synthèse!$I$21 -> 18324875 | J6: =Synthèse!$I$1 -> 46081 | K6: SAL | L6: 6413000 | N6: ="CE et CN "&PROPER(TEXT($J6,"mmm aaaa")) -> CE et CN Févr 2026 | O6: =Synthèse!$V$21+Synthèse!$W$21 -> 780835
A7: =Synthèse!$I$1 -> 46081 | B7: SAL | C7: 6634000 | E7: ="Transport "&PROPER(TEXT($A7,"mmm aaaa")) -> Transport Févr 2026 | F7: =Synthèse!$J$21 -> 390000 | J7: =Synthèse!$I$1 -> 46081 | K7: SAL | L7: 6414000 | N7: ="TA "&PROPER(TEXT($A7,"mmm aaaa")) -> TA Févr 2026 | O7: =Synthèse!$X$21 -> 73301
A8: =Synthèse!$I$1 -> 46081 | B8: SAL | C8: 4220000 | D8: =Synthèse!$C7 -> SAL0001 | E8: ="Salaire net "&Synthèse!$A7&" "&PROPER(TEXT($A8,"mmm aaaa")) -> Salaire net ELIE MOUSSA Févr 2026 | G8: =Synthèse!$K7 -> 293528 | J8: =Synthèse!$I$1 -> 46081 | K8: SAL | L8: 6415000 | N8: ="FDFP "&PROPER(TEXT($A8,"mmm aaaa")) -> FDFP Févr 2026 | O8: =Synthèse!$Y$21 -> 219900
A9: =Synthèse!$I$1 -> 46081 | B9: SAL | C9: 4220000 | D9: =Synthèse!$C8 -> SAL0003 | E9: ="Salaire net "&Synthèse!$A8&" "&PROPER(TEXT($A9,"mmm aaaa")) -> Salaire net TANGARA FANTA Févr 2026 | G9: =Synthèse!$K8 -> 2509418 | J9: =Synthèse!$I$1 -> 46081 | K9: SAL | L9: 6641010 | N9: ="CNPS et AM Employeur "&PROPER(TEXT($A9,"mmm aaaa")) -> CNPS et AM Employeur Févr 2026 | O9: =Synthèse!$Q$21+Synthèse!$R$21 -> 1221481.5
A10: =Synthèse!$I$1 -> 46081 | B10: SAL | C10: 4220000 | D10: =Synthèse!$C9 -> SAL0002 | E10: ="Salaire net "&Synthèse!$A9&" "&PROPER(TEXT($A10,"mmm aaaa")) -> Salaire net OUATTARA ABDOULAYE Févr 2026 | G10: =Synthèse!$K9 -> 257524 | J10: =Synthèse!$I$1 -> 46081 | K10: SAL | L10: 6641020 | N10: ="CMU Employeur "&PROPER(TEXT($A10,"mmm aaaa")) -> CMU Employeur Févr 2026 | O10: =Synthèse!$U$21 -> 17500
A11: =Synthèse!$I$1 -> 46081 | B11: SAL | C11: 4220000 | D11: =Synthèse!$C10 -> SAL0004 | E11: ="Salaire net "&Synthèse!$A10&" "&PROPER(TEXT($A11,"mmm aaaa")) -> Salaire net KARAMOKO MARCEL Févr 2026 | G11: =Synthèse!$K10 -> 1338346 | J11: =Synthèse!$I$1 -> 46081 | K11: SAL | L11: 6641050 | N11: ="PF "&PROPER(TEXT($A11,"mmm aaaa")) -> PF Févr 2026 | O11: =Synthèse!$S$21 -> 48750
A12: =Synthèse!$I$1 -> 46081 | B12: SAL | C12: 4220000 | D12: =Synthèse!$C11 -> SAL0007 | E12: ="Salaire net "&Synthèse!$A11&" "&PROPER(TEXT($A12,"mmm aaaa")) -> Salaire net DAN CESAR Févr 2026 | G12: =Synthèse!$K11 -> 328206 | J12: =Synthèse!$I$1 -> 46081 | K12: SAL | L12: 6641040 | N12: ="AT "&PROPER(TEXT($A12,"mmm aaaa")) -> AT Févr 2026 | O12: =Synthèse!$T$21 -> 48750
A13: =Synthèse!$I$1 -> 46081 | B13: SAL | C13: 4220000 | D13: =Synthèse!$C12 -> SAL0008 | E13: ="Salaire net "&Synthèse!$A12&" "&PROPER(TEXT($A13,"mmm aaaa")) -> Salaire net ASSI BONAVENTURE Févr 2026 | G13: =Synthèse!$K12 -> 208846 | J13: =Synthèse!$I$1 -> 46081 | K13: SAL | L13: 4311000 | M13: FNR0036 | N13: ="PF "&PROPER(TEXT($A13,"mmm aaaa")) -> PF Févr 2026 | P13: =$O$11 -> 48750
A14: =Synthèse!$I$1 -> 46081 | B14: SAL | C14: 4220000 | D14: =Synthèse!$C13 -> SAL0010 | E14: ="Salaire net "&Synthèse!$A13&" "&PROPER(TEXT($A14,"mmm aaaa")) -> Salaire net BESONGACHE PAUL Févr 2026 | G14: =Synthèse!$K13 -> 4143983 | J14: =Synthèse!$I$1 -> 46081 | K14: SAL | L14: 4312000 | M14: FNR0036 | N14: ="AT "&PROPER(TEXT($A14,"mmm aaaa")) -> AT Févr 2026 | P14: =$O$12 -> 48750
A15: =Synthèse!$I$1 -> 46081 | B15: SAL | C15: 4220000 | D15: =Synthèse!$C14 -> SAL0012 | E15: ="Salaire net "&Synthèse!$A14&" "&PROPER(TEXT($A15,"mmm aaaa")) -> Salaire net KONAN JEAN YVES Févr 2026 | G15: =Synthèse!$K14 -> 738570 | J15: =Synthèse!$I$1 -> 46081 | K15: SAL | L15: 4318010 | M15: FNR0036 | N15: ="CNPS et AM Employeur "&PROPER(TEXT($A15,"mmm aaaa")) -> CNPS et AM Employeur Févr 2026 | P15: =$O$9 -> 1221481.5
A16: =Synthèse!$I$1 -> 46081 | B16: SAL | C16: 4220000 | D16: =Synthèse!$C15 -> SAL0013 | E16: ="Salaire net "&Synthèse!$A15&" "&PROPER(TEXT($A16,"mmm aaaa")) -> Salaire net SANOGO MORIBA Févr 2026 | G16: =Synthèse!$K15 -> 205477 | J16: =Synthèse!$I$1 -> 46081 | K16: SAL | L16: 4318020 | M16: FNR0036 | N16: ="CMU Employeur "&PROPER(TEXT($A16,"mmm aaaa")) -> CMU Employeur Févr 2026 | P16: =$O$10 -> 17500
A17: =Synthèse!$I$1 -> 46081 | B17: SAL | C17: 4220000 | D17: =Synthèse!$C16 -> SAL0014 | E17: ="Salaire net "&Synthèse!$A16&" "&PROPER(TEXT($A17,"mmm aaaa")) -> Salaire net COULIBALY TEMAN Févr 2026 | G17: =Synthèse!$K16 -> 410205 | J17: =Synthèse!$I$1 -> 46081 | K17: SAL | L17: 4472000 | M17: FNR0121 | N17: ="CE, CN, TA et FDFP "&PROPER(TEXT($A17,"mmm aaaa")) -> CE, CN, TA et FDFP Févr 2026 | P17: =$O$6+$O$7+$O$8 -> 1074036
A18: =Synthèse!$I$1 -> 46081 | B18: SAL | C18: 4220000 | D18: =Synthèse!$C17 -> SAL0015 | E18: ="Salaire net "&Synthèse!$A17&" "&PROPER(TEXT($A18,"mmm aaaa")) -> Salaire net KOUACHY DJOMAN PACOME Févr 2026 | G18: =Synthèse!$K17 -> 462350 | J18: Total | O18: =SUM(O6:O17) -> 2410517.5 | P18: =SUM(P6:P17) -> 2410517.5
A19: =Synthèse!$I$1 -> 46081 | B19: SAL | C19: 4220000 | D19: =Synthèse!$C18 -> SAL0017 | E19: ="Salaire net "&Synthèse!$A18&" "&PROPER(TEXT($A19,"mmm aaaa")) -> Salaire net BLONDE MARCEL Févr 2026 | G19: =Synthèse!$K18 -> 559523 | O19: =O18-P18 -> 0
A20: =Synthèse!$I$1 -> 46081 | B20: SAL | C20: 4220000 | D20: =Synthèse!$C19 -> SAL0018 | E20: ="Salaire net "&Synthèse!$A19&" "&PROPER(TEXT($A20,"mmm aaaa")) -> Salaire net GNADOU PAULE MARIANNE Févr 2026 | G20: =Synthèse!$K19 -> 2317096 | O20: =IF($O$19=0,"Equilibré",IF($O$19<0,"Crédit >Débit",IF($O$19>0,"Débit>Crédit",""))) -> Equilibré
A21: =Synthèse!$I$1 -> 46081 | B21: SAL | C21: 4313000 | D21: FNR0036 | E21: ="CNPS Salariés "&PROPER(TEXT($A21,"mmm aaaa")) -> CNPS Salariés Févr 2026 | G21: =Synthèse!$M$21 -> 993411
A22: =Synthèse!$I$1 -> 46081 | B22: SAL | C22: 4318020 | D22: FNR0036 | E22: ="CMU Salariés "&PROPER(TEXT($A22,"mmm aaaa")) -> CMU Salariés Févr 2026 | G22: =Synthèse!$N$21 -> 17500
A23: =Synthèse!$I$1 -> 46081 | B23: SAL | C23: 4472000 | D23: FNR0121 | E23: ="ITS Salariés "&PROPER(TEXT($A23,"mmm aaaa")) -> ITS Salariés Févr 2026 | G23: =Synthèse!$O$21 -> 3930892
A24: Total | F24: =SUM(F6:F23) -> 18714875 | G24: =SUM(G6:G23) -> 18714875
F25: =F24-G24 -> 0
F26: =IF($F$25=0,"Equilibré",IF($F$25<0,"Crédit >Débit",IF($F$25>0,"Débit>Crédit",""))) -> Equilibré
T31: Modifier LP
O32: Livre de Paie | Q32: Relevé bancaire | S32: Relevé - LP
O33: SAL0001 | P33: 293528 | Q33: SAL0001 | R33: 293528 | S33: =R33-P33 -> 0
O34: SAL0003 | P34: 2509418 | Q34: SAL0003 | R34: 2509418 | S34: =R34-P34 -> 0
O35: SAL0002 | P35: 257524 | Q35: SAL0002 | R35: 257524 | S35: =R35-P35 -> 0
O36: SAL0004 | P36: 1338346 | Q36: SAL0004 | R36: 1338346 | S36: =R36-P36 -> 0
O37: SAL0007 | P37: 328206 | Q37: SAL0007 | R37: 328206 | S37: =R37-P37 -> 0
O38: SAL0008 | P38: 208846 | Q38: SAL0008 | R38: 208846 | S38: =R38-P38 -> 0
O39: SAL0010 | P39: 4143983 | Q39: SAL0010 | R39: 4143983 | S39: =R39-P39 -> 0
O40: SAL0012 | P40: 738570 | Q40: SAL0012 | R40: 738570 | S40: =R40-P40 -> 0
O41: SAL0013 | P41: 205477 | Q41: SAL0013 | R41: 205477 | S41: =R41-P41 -> 0
O42: SAL0014 | P42: 410205 | Q42: SAL0014 | R42: 410205 | S42: =R42-P42 -> 0
O43: SAL0015 | P43: 462350 | Q43: SAL0015 | R43: 462350 | S43: =R43-P43 -> 0
O44: SAL0017 | P44: 559523 | Q44: SAL0017 | R44: 559523 | S44: =R44-P44 -> 0
O45: SAL0018 | P45: 2317096 | Q45: SAL0018 | R45: 2317096 | S45: =R45-P45 -> 0
P46: =SUM(P33:P45) -> 13773072 | R46: =SUM(R33:R45) -> 13773072 | S46: =SUM(S33:S45) -> 0

Sheet ELIE MOUSSA
A1: CALCULATEUR DE SALAIRE BRUT | F1: Synthèse
A3: Salarié | B3: ELIE MOUSSA
A4: Statut | B4: Employé
A5: Local | B5: Non
A6: Situation | B6: M
A7: Nb Enfants | B7: 0
A8: Parts | B8: =IF(IF($B$4="Stagiaire",0,IF(AND($B$6 = "C", $B$7 = 0), 1,IF(AND($B$6 = "C", $B$7 = 1), 2,IF(AND($B$6 = "C", $B$7 = 2), 2.5,IF(AND($B$6 = "C", $B$7 = 3), 3,IF(AND($B$6 = "C", $B$7 = 4), 3.5,IF(AND($B$6 = "C", $B$7 = 5), 4,IF(AND($B$6 = "C", $B$7 = 6), 4.5,IF(AND($B$6 = "M", $B$7 = 0), 2,IF(AND($B$6 = "M", $B$7 = 1), 2.5,IF(AND($B$6 = "M", $B$7 = 2), 3,IF(AND($B$6 = "M", $B$7 = 3), 3.5,IF(AND($B$6 = "M", $B$7 = 4), 4,IF(AND($B$6 = "M", $B$7 = 5), 4.5,IF(AND($B$6 = "M", $B$7 = 6), 5,"")))))))))))))))<=5,IF($B$4="Stagiaire",0,IF(AND($B$6 = "C", $B$7 = 0), 1,IF(AND($B$6 = "C", $B$7 = 1), 2,IF(AND($B$6 = "C", $B$7 = 2), 2.5,IF(AND($B$6 = "C", $B$7 = 3), 3,IF(AND($B$6 = "C", $B$7 = 4), 3.5,IF(AND($B$6 = "C", $B$7 = 5), 4,IF(AND($B$6 = "C", $B$7 = 6), 4.5,IF(AND($B$6 = "M", $B$7 = 0), 2,IF(AND($B$6 = "M", $B$7 = 1), 2.5,IF(AND($B$6 = "M", $B$7 = 2), 3,IF(AND($B$6 = "M", $B$7 = 3), 3.5,IF(AND($B$6 = "M", $B$7 = 4), 4,IF(AND($B$6 = "M", $B$7 = 5), 4.5,IF(AND($B$6 = "M", $B$7 = 6), 5,""))))))))))))))),5) -> 2
A9: Charge CMU | B9: Partiel
A11: Rubrique | B11: Type | C11: Montant salarié | D11: Montant employeur
A12: Salaire catégoriel | B12: Gain
A13: Sursalaire | B13: Gain
A14: Salaire brut | B14: Gain | C14: 315719
A15: ITS avant RICF | B15: Retenue | C15: =IF($B$4="Stagiaire",0, ROUND( IF(AND($C14=0,$C14<=75000),0, IF(AND($C14>=75001,$C14<=240000),ROUND(($C14-75001)*0.16,0)+0, IF(AND($C14>=240001,$C14<=800000),ROUND(($C14-240001)*0.21,0)+0+26400, IF(AND($C14>=800001,$C14<=2400000),ROUND(($C14-800001)*0.24,0)+0+26400+117600, IF(AND($C14>=2400001,$C14<=8000000),ROUND(($C14-2400001)*0.28,0)+0+26400+117600+384000, IF($C14>=8000001,ROUND(($C14-8000001)*0.32,0)+0+26400+117600+384000+1568000, 0)))))),0)) -> 42301
A16: RICF | B16: Retenue | C16: =IF($B$4="Stagiaire",0, ROUND( IF($B$8=1,0, IF($B$8=1.5,5500, IF($B$8=2,11000, IF($B$8=2.5,16500, IF($B$8=3,22000, IF($B$8=3.5,27500, IF($B$8=4,33000, IF($B$8=4.5,38500, IF($B$8=5,44000, 0))))))))),0)) -> 11000
A17: ITS après RICF | B17: Retenue | C17: =IF($C$15-$C$16<0,0,$C$15-$C$16) -> 31301
A18: Contribution Employeur | B18: Retenue | D18: =IF(OR($B$4="Stagiaire",$B$5="Oui",,$B$5=""),0, ROUND($C$14*0.092,0)) -> 29046
A19: Contribution Nationale | B19: Retenue | D19: =IF($B$4="Stagiaire",0, ROUND($C$14*0.012,0)) -> 3789
A20: Taxe d'apprentissage | B20: Retenue | D20: =IF($B$4="Stagiaire",0, ROUND($C$14*0.004,0)) -> 1263
A21: FDFP TFPC | B21: Retenue | D21: =IF($B$4="Stagiaire",0, ROUND($C$14*0.012,0)) -> 3789
A22: FDFP Regul | B22: Retenue | D22: =0 -> 0 | F22: Données CIFIDEC
A23: CNPS salarié | B23: Retenue | C23: =IF($B$4="Stagiaire",0, ROUND( IF($C$14<75000,75000*0.063, IF(AND($C$14>=75000,$C$14<=3375000),$C$14*0.063, IF($C$14>3375000,3375000*0.063,0))), 0)) -> 19890 | G23: =C23-ROUND(F23,0) -> 19890
A24: CNPS employeur | B24: Retenue | D24: =IF($B$4="Stagiaire",0, ROUND( IF($C$14<75000,75000*0.077, IF(AND($C$14>=75000,$C$14<=3375000),$C$14*0.077, IF($C$14>3375000,3375000*0.077,0))), 0)) -> 24310 | G24: =D24-ROUND(F24,0) -> 24310
A25: Prestations familiales | B25: Retenue | D25: =IF($B$4="Stagiaire",0, ROUND( IF($C$14<75000,75000*0.05, IF($C$14>=75000,75000*0.05, IF($C$14>3375000,75000*0.05,0))), 0)) -> 3750
A26: Assurance maternité | B26: Retenue | D26: =IF($B$4="Stagiaire",0, ROUND( IF($C$14<75000,75000*0.0075, IF($C$14>=75000,75000*0.0075, IF($C$14>3375000,75000*0.0075,0))), 2)) -> 562.5
A27: Accident de travail | B27: Retenue | D27: =IF($B$4="Stagiaire",0, ROUND( IF($C$14<75000,75000*0.05, IF($C$14>=75000,75000*0.05, IF($C$14>3375000,75000*0.05,0))), 0)) -> 3750
A28: CMU salarié | B28: Retenue | C28: =IF($B$6="C",ROUND(IF($B$9="Total",0,($B$7+1)*500),0),ROUND(IF($B$9="Total",0,($B$7+2)*500),0)) -> 1000
A29: CMU employeur | B29: Retenue | D29: =C28 -> 1000
A30: Indemnité de transport | B30: Gain | C30: =30000 -> 30000
A31: Net à payer | B31: Gain | C31: =IF($B$4="Stagiaire",$C$30, C14-C17-C23-C28+C30) -> 293528
A32: Charges salariales | C32: =C17+C23+C28 -> 52191
A33: Charges patronales | D33: =D18+D19+D20+D21+D22+D24+D25+D26+D27+D29 -> 71259.5

Sheet TANGARA FANTA
A1: CALCULATEUR DE SALAIRE BRUT | F1: Synthèse
A3: Salarié | B3: TANGARA FANTA
A4: Statut | B4: Employé
A5: Local | B5: Oui
A6: Situation | B6: M
A7: Nb Enfants | B7: 0
A8: Parts | B8: =IF(IF($B$4="Stagiaire",0,IF(AND($B$6 = "C", $B$7 = 0), 1,IF(AND($B$6 = "C", $B$7 = 1), 2,IF(AND($B$6 = "C", $B$7 = 2), 2.5,IF(AND($B$6 = "C", $B$7 = 3), 3,IF(AND($B$6 = "C", $B$7 = 4), 3.5,IF(AND($B$6 = "C", $B$7 = 5), 4,IF(AND($B$6 = "C", $B$7 = 6), 4.5,IF(AND($B$6 = "M", $B$7 = 0), 2,IF(AND($B$6 = "M", $B$7 = 1), 2.5,IF(AND($B$6 = "M", $B$7 = 2), 3,IF(AND($B$6 = "M", $B$7 = 3), 3.5,IF(AND($B$6 = "M", $B$7 = 4), 4,IF(AND($B$6 = "M", $B$7 = 5), 4.5,IF(AND($B$6 = "M", $B$7 = 6), 5,"")))))))))))))))<=5,IF($B$4="Stagiaire",0,IF(AND($B$6 = "C", $B$7 = 0), 1,IF(AND($B$6 = "C", $B$7 = 1), 2,IF(AND($B$6 = "C", $B$7 = 2), 2.5,IF(AND($B$6 = "C", $B$7 = 3), 3,IF(AND($B$6 = "C", $B$7 = 4), 3.5,IF(AND($B$6 = "C", $B$7 = 5), 4,IF(AND($B$6 = "C", $B$7 = 6), 4.5,IF(AND($B$6 = "M", $B$7 = 0), 2,IF(AND($B$6 = "M", $B$7 = 1), 2.5,IF(AND($B$6 = "M", $B$7 = 2), 3,IF(AND($B$6 = "M", $B$7 = 3), 3.5,IF(AND($B$6 = "M", $B$7 = 4), 4,IF(AND($B$6 = "M", $B$7 = 5), 4.5,IF(AND($B$6 = "M", $B$7 = 6), 5,""))))))))))))))),5) -> 2
A9: Charge CMU | B9: Partiel
A11: Rubrique | B11: Type | C11: Montant salarié | D11: Montant employeur
A12: Salaire catégoriel | B12: Gain
A13: Sursalaire | B13: Gain
A14: Salaire brut | B14: Gain | C14: 3525060
A15: ITS avant RICF | B15: Retenue | C15: =IF($B$4="Stagiaire",0, ROUND( IF(AND($C14=0,$C14<=75000),0, IF(AND($C14>=75001,$C14<=240000),ROUND(($C14-75001)*0.16,0)+0, IF(AND($C14>=240001,$C14<=800000),ROUND(($C14-240001)*0.21,0)+0+26400, IF(AND($C14>=800001,$C14<=2400000),ROUND(($C14-800001)*0.24,0)+0+26400+117600, IF(AND($C14>=2400001,$C14<=8000000),ROUND(($C14-2400001)*0.28,0)+0+26400+117600+384000, IF($C14>=8000001,ROUND(($C14-8000001)*0.32,0)+0+26400+117600+384000+1568000, 0)))))),0)) -> 843017
A16: RICF | B16: Retenue | C16: =IF($B$4="Stagiaire",0, ROUND( IF($B$8=1,0, IF($B$8=1.5,5500, IF($B$8=2,11000, IF($B$8=2.5,16500, IF($B$8=3,22000, IF($B$8=3.5,27500, IF($B$8=4,33000, IF($B$8=4.5,38500, IF($B$8=5,44000, 0))))))))),0)) -> 11000
A17: ITS après RICF | B17: Retenue | C17: =IF($C$15-$C$16<0,0,$C$15-$C$16) -> 832017
A18: Contribution Employeur | B18: Retenue | D18: =IF(OR($B$4="Stagiaire",$B$5="Oui",,$B$5=""),0, ROUND($C$14*0.092,0)) -> 0
A19: Contribution Nationale | B19: Retenue | D19: =IF($B$4="Stagiaire",0, ROUND($C$14*0.012,0)) -> 42301
A20: Taxe d'apprentissage | B20: Retenue | D20: =IF($B$4="Stagiaire",0, ROUND($C$14*0.004,0)) -> 14100
A21: FDFP TFPC | B21: Retenue | D21: =IF($B$4="Stagiaire",0, ROUND($C$14*0.012,0)) -> 42301
A22: FDFP Regul | B22: Retenue | D22: =0 -> 0 | F22: Données CIFIDEC
A23: CNPS salarié | B23: Retenue | C23: =IF($B$4="Stagiaire",0, ROUND( IF($C$14<75000,75000*0.063, IF(AND($C$14>=75000,$C$14<=3375000),$C$14*0.063, IF($C$14>3375000,3375000*0.063,0))), 0)) -> 212625 | G23: =C23-ROUND(F23,0) -> 212625
A24: CNPS employeur | B24: Retenue | D24: =IF($B$4="Stagiaire",0, ROUND( IF($C$14<75000,75000*0.077, IF(AND($C$14>=75000,$C$14<=3375000),$C$14*0.077, IF($C$14>3375000,3375000*0.077,0))), 0)) -> 259875 | G24: =D24-ROUND(F24,0) -> 259875
A25: Prestations familiales | B25: Retenue | D25: =IF($B$4="Stagiaire",0, ROUND( IF($C$14<75000,75000*0.05, IF($C$14>=75000,75000*0.05, IF($C$14>3375000,75000*0.05,0))), 0)) -> 3750
A26: Assurance maternité | B26: Retenue | D26: =IF($B$4="Stagiaire",0, ROUND( IF($C$14<75000,75000*0.0075, IF($C$14>=75000,75000*0.0075, IF($C$14>3375000,75000*0.0075,0))), 2)) -> 562.5
A27: Accident de travail | B27: Retenue | D27: =IF($B$4="Stagiaire",0, ROUND( IF($C$14<75000,75000*0.05, IF($C$14>=75000,75000*0.05, IF($C$14>3375000,75000*0.05,0))), 0)) -> 3750
A28: CMU salarié | B28: Retenue | C28: =IF($B$6="C",ROUND(IF($B$9="Total",0,($B$7+1)*500),0),ROUND(IF($B$9="Total",0,($B$7+2)*500),0)) -> 1000
A29: CMU employeur | B29: Retenue | D29: =C28 -> 1000
A30: Indemnité de transport | B30: Gain | C30: =30000 -> 30000
A31: Net à payer | B31: Gain | C31: =IF($B$4="Stagiaire",$C$30, C14-C17-C23-C28+C30) -> 2509418
A32: Charges salariales | C32: =C17+C23+C28 -> 1045642
A33: Charges patronales | D33: =D18+D20+D21+D22+D24+D25+D26+D27+D29 -> 325338.5

Sheet OUATTARA ABDOULAYE
A1: CALCULATEUR DE SALAIRE BRUT | F1: Synthèse
A3: Salarié | B3: OUATTARA ABDOULAYE
A4: Statut | B4: Employé
A5: Local | B5: Oui
A6: Situation | B6: M
A7: Nb Enfants | B7: 4
A8: Parts | B8: =IF(IF($B$4="Stagiaire",0,IF(AND($B$6 = "C", $B$7 = 0), 1,IF(AND($B$6 = "C", $B$7 = 1), 2,IF(AND($B$6 = "C", $B$7 = 2), 2.5,IF(AND($B$6 = "C", $B$7 = 3), 3,IF(AND($B$6 = "C", $B$7 = 4), 3.5,IF(AND($B$6 = "C", $B$7 = 5), 4,IF(AND($B$6 = "C", $B$7 = 6), 4.5,IF(AND($B$6 = "M", $B$7 = 0), 2,IF(AND($B$6 = "M", $B$7 = 1), 2.5,IF(AND($B$6 = "M", $B$7 = 2), 3,IF(AND($B$6 = "M", $B$7 = 3), 3.5,IF(AND($B$6 = "M", $B$7 = 4), 4,IF(AND($B$6 = "M", $B$7 = 5), 4.5,IF(AND($B$6 = "M", $B$7 = 6), 5,"")))))))))))))))<=5,IF($B$4="Stagiaire",0,IF(AND($B$6 = "C", $B$7 = 0), 1,IF(AND($B$6 = "C", $B$7 = 1), 2,IF(AND($B$6 = "C", $B$7 = 2), 2.5,IF(AND($B$6 = "C", $B$7 = 3), 3,IF(AND($B$6 = "C", $B$7 = 4), 3.5,IF(AND($B$6 = "C", $B$7 = 5), 4,IF(AND($B$6 = "C", $B$7 = 6), 4.5,IF(AND($B$6 = "M", $B$7 = 0), 2,IF(AND($B$6 = "M", $B$7 = 1), 2.5,IF(AND($B$6 = "M", $B$7 = 2), 3,IF(AND($B$6 = "M", $B$7 = 3), 3.5,IF(AND($B$6 = "M", $B$7 = 4), 4,IF(AND($B$6 = "M", $B$7 = 5), 4.5,IF(AND($B$6 = "M", $B$7 = 6), 5,""))))))))))))))),5) -> 4
A9: Charge CMU | B9: Partiel
A11: Rubrique | B11: Type | C11: Montant salarié | D11: Montant employeur
A12: Salaire catégoriel | B12: Gain
A13: Sursalaire | B13: Gain
A14: Salaire brut | B14: Gain | C14: 246023
A15: ITS avant RICF | B15: Retenue | C15: =IF($B$4="Stagiaire",0, ROUND( IF(AND($C14=0,$C14<=75000),0, IF(AND($C14>=75001,$C14<=240000),ROUND(($C14-75001)*0.16,0)+0, IF(AND($C14>=240001,$C14<=800000),ROUND(($C14-240001)*0.21,0)+0+26400, IF(AND($C14>=800001,$C14<=2400000),ROUND(($C14-800001)*0.24,0)+0+26400+117600, IF(AND($C14>=2400001,$C14<=8000000),ROUND(($C14-2400001)*0.28,0)+0+26400+117600+384000, IF($C14>=8000001,ROUND(($C14-8000001)*0.32,0)+0+26400+117600+384000+1568000, 0)))))),0)) -> 27665
A16: RICF | B16: Retenue | C16: =IF($B$4="Stagiaire",0, ROUND( IF($B$8=1,0, IF($B$8=1.5,5500, IF($B$8=2,11000, IF($B$8=2.5,16500, IF($B$8=3,22000, IF($B$8=3.5,27500, IF($B$8=4,33000, IF($B$8=4.5,38500, IF($B$8=5,44000, 0))))))))),0)) -> 33000
A17: ITS après RICF | B17: Retenue | C17: =IF($C$15-$C$16<0,0,$C$15-$C$16) -> 0
A18: Contribution Employeur | B18: Retenue | D18: =IF(OR($B$4="Stagiaire",$B$5="Oui",,$B$5=""),0, ROUND($C$14*0.092,0)) -> 0
A19: Contribution Nationale | B19: Retenue | D19: =IF($B$4="Stagiaire",0, ROUND($C$14*0.012,0)) -> 2952
A20: Taxe d'apprentissage | B20: Retenue | D20: =IF($B$4="Stagiaire",0, ROUND($C$14*0.004,0)) -> 984
A21: FDFP TFPC | B21: Retenue | D21: =IF($B$4="Stagiaire",0, ROUND($C$14*0.012,0)) -> 2952
A22: FDFP Regul | B22: Retenue | D22: =0 -> 0 | F22: Données CIFIDEC
A23: CNPS salarié | B23: Retenue | C23: =IF($B$4="Stagiaire",0, ROUND( IF($C$14<75000,75000*0.063, IF(AND($C$14>=75000,$C$14<=3375000),$C$14*0.063, IF($C$14>3375000,3375000*0.063,0))), 0)) -> 15499 | G23: =C23-ROUND(F23,0) -> 15499
A24: CNPS employeur | B24: Retenue | D24: =IF($B$4="Stagiaire",0, ROUND( IF($C$14<75000,75000*0.077, IF(AND($C$14>=75000,$C$14<=3375000),$C$14*0.077, IF($C$14>3375000,3375000*0.077,0))), 0)) -> 18944 | G24: =D24-ROUND(F24,0) -> 18944
A25: Prestations familiales | B25: Retenue | D25: =IF($B$4="Stagiaire",0, ROUND( IF($C$14<75000,75000*0.05, IF($C$14>=75000,75000*0.05, IF($C$14>3375000,75000*0.05,0))), 0)) -> 3750
A26: Assurance maternité | B26: Retenue | D26: =IF($B$4="Stagiaire",0, ROUND( IF($C$14<75000,75000*0.0075, IF($C$14>=75000,75000*0.0075, IF($C$14>3375000,75000*0.0075,0))), 2)) -> 562.5
A27: Accident de travail | B27: Retenue | D27: =IF($B$4="Stagiaire",0, ROUND( IF($C$14<75000,75000*0.05, IF($C$14>=75000,75000*0.05, IF($C$14>3375000,75000*0.05,0))), 0)) -> 3750
A28: CMU salarié | B28: Retenue | C28: =IF($B$6="C",ROUND(IF($B$9="Total",0,($B$7+1)*500),0),ROUND(IF($B$9="Total",0,($B$7+2)*500),0)) -> 3000
A29: CMU employeur | B29: Retenue | D29: =C28 -> 3000
A30: Indemnité de transport | B30: Gain | C30: =30000 -> 30000
A31: Net à payer | B31: Gain | C31: =IF($B$4="Stagiaire",$C$30, C14-C17-C23-C28+C30) -> 257524
A32: Charges salariales | C32: =C17+C23+C28 -> 18499
A33: Charges patronales | D33: =D18+D20+D21+D22+D24+D25+D26+D27+D29 -> 33942.5

Sheet KARAMOKO MARCEL
A1: CALCULATEUR DE SALAIRE BRUT | F1: Synthèse
A3: Salarié | B3: KARAMOKO MARCEL
A4: Statut | B4: Employé
A5: Local | B5: Oui
A6: Situation | B6: C
A7: Nb Enfants | B7: 0
A8: Parts | B8: =IF(IF($B$4="Stagiaire",0,IF(AND($B$6 = "C", $B$7 = 0), 1,IF(AND($B$6 = "C", $B$7 = 1), 2,IF(AND($B$6 = "C", $B$7 = 2), 2.5,IF(AND($B$6 = "C", $B$7 = 3), 3,IF(AND($B$6 = "C", $B$7 = 4), 3.5,IF(AND($B$6 = "C", $B$7 = 5), 4,IF(AND($B$6 = "C", $B$7 = 6), 4.5,IF(AND($B$6 = "M", $B$7 = 0), 2,IF(AND($B$6 = "M", $B$7 = 1), 2.5,IF(AND($B$6 = "M", $B$7 = 2), 3,IF(AND($B$6 = "M", $B$7 = 3), 3.5,IF(AND($B$6 = "M", $B$7 = 4), 4,IF(AND($B$6 = "M", $B$7 = 5), 4.5,IF(AND($B$6 = "M", $B$7 = 6), 5,"")))))))))))))))<=5,IF($B$4="Stagiaire",0,IF(AND($B$6 = "C", $B$7 = 0), 1,IF(AND($B$6 = "C", $B$7 = 1), 2,IF(AND($B$6 = "C", $B$7 = 2), 2.5,IF(AND($B$6 = "C", $B$7 = 3), 3,IF(AND($B$6 = "C", $B$7 = 4), 3.5,IF(AND($B$6 = "C", $B$7 = 5), 4,IF(AND($B$6 = "C", $B$7 = 6), 4.5,IF(AND($B$6 = "M", $B$7 = 0), 2,IF(AND($B$6 = "M", $B$7 = 1), 2.5,IF(AND($B$6 = "M", $B$7 = 2), 3,IF(AND($B$6 = "M", $B$7 = 3), 3.5,IF(AND($B$6 = "M", $B$7 = 4), 4,IF(AND($B$6 = "M", $B$7 = 5), 4.5,IF(AND($B$6 = "M", $B$7 = 6), 5,""))))))))))))))),5) -> 1
A9: Charge CMU | B9: Partiel
A11: Rubrique | B11: Type | C11: Montant salarié | D11: Montant employeur
A12: Salaire catégoriel | B12: Gain
A13: Sursalaire | B13: Gain
A14: Salaire brut | B14: Gain | C14: 1808961
A15: ITS avant RICF | B15: Retenue | C15: =IF($B$4="Stagiaire",0, ROUND( IF(AND($C14=0,$C14<=75000),0, IF(AND($C14>=75001,$C14<=240000),ROUND(($C14-75001)*0.16,0)+0, IF(AND($C14>=240001,$C14<=800000),ROUND(($C14-240001)*0.21,0)+0+26400, IF(AND($C14>=800001,$C14<=2400000),ROUND(($C14-800001)*0.24,0)+0+26400+117600, IF(AND($C14>=2400001,$C14<=8000000),ROUND(($C14-2400001)*0.28,0)+0+26400+117600+384000, IF($C14>=8000001,ROUND(($C14-8000001)*0.32,0)+0+26400+117600+384000+1568000, 0)))))),0)) -> 386150
A16: RICF | B16: Retenue | C16: =IF($B$4="Stagiaire",0, ROUND( IF($B$8=1,0, IF($B$8=1.5,5500, IF($B$8=2,11000, IF($B$8=2.5,16500, IF($B$8=3,22000, IF($B$8=3.5,27500, IF($B$8=4,33000, IF($B$8=4.5,38500, IF($B$8=5,44000, 0))))))))),0)) -> 0
A17: ITS après RICF | B17: Retenue | C17: =IF($C$15-$C$16<0,0,$C$15-$C$16) -> 386150
A18: Contribution Employeur | B18: Retenue | D18: =IF(OR($B$4="Stagiaire",$B$5="Oui",,$B$5=""),0, ROUND($C$14*0.092,0)) -> 0
A19: Contribution Nationale | B19: Retenue | D19: =IF($B$4="Stagiaire",0, ROUND($C$14*0.012,0)) -> 21708
A20: Taxe d'apprentissage | B20: Retenue | D20: =IF($B$4="Stagiaire",0, ROUND($C$14*0.004,0)) -> 7236
A21: FDFP TFPC | B21: Retenue | D21: =IF($B$4="Stagiaire",0, ROUND($C$14*0.012,0)) -> 21708
A22: FDFP Regul | B22: Retenue | D22: =0 -> 0 | F22: Données CIFIDEC
A23: CNPS salarié | B23: Retenue | C23: =IF($B$4="Stagiaire",0, ROUND( IF($C$14<75000,75000*0.063, IF(AND($C$14>=75000,$C$14<=3375000),$C$14*0.063, IF($C$14>3375000,3375000*0.063,0))), 0)) -> 113965 | G23: =C23-ROUND(F23,0) -> 113965
A24: CNPS employeur | B24: Retenue | D24: =IF($B$4="Stagiaire",0, ROUND( IF($C$14<75000,75000*0.077, IF(AND($C$14>=75000,$C$14<=3375000),$C$14*0.077, IF($C$14>3375000,3375000*0.077,0))), 0)) -> 139290 | G24: =D24-ROUND(F24,0) -> 139290
A25: Prestations familiales | B25: Retenue | D25: =IF($B$4="Stagiaire",0, ROUND( IF($C$14<75000,75000*0.05, IF($C$14>=75000,75000*0.05, IF($C$14>3375000,75000*0.05,0))), 0)) -> 3750
A26: Assurance maternité | B26: Retenue | D26: =IF($B$4="Stagiaire",0, ROUND( IF($C$14<75000,75000*0.0075, IF($C$14>=75000,75000*0.0075, IF($C$14>3375000,75000*0.0075,0))), 2)) -> 562.5
A27: Accident de travail | B27: Retenue | D27: =IF($B$4="Stagiaire",0, ROUND( IF($C$14<75000,75000*0.05, IF($C$14>=75000,75000*0.05, IF($C$14>3375000,75000*0.05,0))), 0)) -> 3750
A28: CMU salarié | B28: Retenue | C28: =IF($B$6="C",ROUND(IF($B$9="Total",0,($B$7+1)*500),0),ROUND(IF($B$9="Total",0,($B$7+2)*500),0)) -> 500
A29: CMU employeur | B29: Retenue | D29: =C28 -> 500
A30: Indemnité de transport | B30: Gain | C30: =30000 -> 30000
A31: Net à payer | B31: Gain | C31: =IF($B$4="Stagiaire",$C$30, C14-C17-C23-C28+C30) -> 1338346
A32: Charges salariales | C32: =C17+C23+C28 -> 500615
A33: Charges patronales | D33: =D18+D20+D21+D22+D24+D25+D26+D27+D29 -> 176796.5

Sheet DAN CESAR
A1: CALCULATEUR DE SALAIRE BRUT | F1: Synthèse
A3: Salarié | B3: DAN CESAR
A4: Statut | B4: Employé
A5: Local | B5: Oui
A6: Situation | B6: M
A7: Nb Enfants | B7: 2
A8: Parts | B8: =IF(IF($B$4="Stagiaire",0,IF(AND($B$6 = "C", $B$7 = 0), 1,IF(AND($B$6 = "C", $B$7 = 1), 2,IF(AND($B$6 = "C", $B$7 = 2), 2.5,IF(AND($B$6 = "C", $B$7 = 3), 3,IF(AND($B$6 = "C", $B$7 = 4), 3.5,IF(AND($B$6 = "C", $B$7 = 5), 4,IF(AND($B$6 = "C", $B$7 = 6), 4.5,IF(AND($B$6 = "M", $B$7 = 0), 2,IF(AND($B$6 = "M", $B$7 = 1), 2.5,IF(AND($B$6 = "M", $B$7 = 2), 3,IF(AND($B$6 = "M", $B$7 = 3), 3.5,IF(AND($B$6 = "M", $B$7 = 4), 4,IF(AND($B$6 = "M", $B$7 = 5), 4.5,IF(AND($B$6 = "M", $B$7 = 6), 5,"")))))))))))))))<=5,IF($B$4="Stagiaire",0,IF(AND($B$6 = "C", $B$7 = 0), 1,IF(AND($B$6 = "C", $B$7 = 1), 2,IF(AND($B$6 = "C", $B$7 = 2), 2.5,IF(AND($B$6 = "C", $B$7 = 3), 3,IF(AND($B$6 = "C", $B$7 = 4), 3.5,IF(AND($B$6 = "C", $B$7 = 5), 4,IF(AND($B$6 = "C", $B$7 = 6), 4.5,IF(AND($B$6 = "M", $B$7 = 0), 2,IF(AND($B$6 = "M", $B$7 = 1), 2.5,IF(AND($B$6 = "M", $B$7 = 2), 3,IF(AND($B$6 = "M", $B$7 = 3), 3.5,IF(AND($B$6 = "M", $B$7 = 4), 4,IF(AND($B$6 = "M", $B$7 = 5), 4.5,IF(AND($B$6 = "M", $B$7 = 6), 5,""))))))))))))))),5) -> 3
A9: Charge CMU | B9: Partiel
A11: Rubrique | B11: Type | C11: Montant salarié | D11: Montant employeur
A12: Salaire catégoriel | B12: Gain
A13: Sursalaire | B13: Gain
A14: Salaire brut | B14: Gain | C14: 349664
A15: ITS avant RICF | B15: Retenue | C15: =IF($B$4="Stagiaire",0, ROUND( IF(AND($C14=0,$C14<=75000),0, IF(AND($C14>=75001,$C14<=240000),ROUND(($C14-75001)*0.16,0)+0, IF(AND($C14>=240001,$C14<=800000),ROUND(($C14-240001)*0.21,0)+0+26400, IF(AND($C14>=800001,$C14<=2400000),ROUND(($C14-800001)*0.24,0)+0+26400+117600, IF(AND($C14>=2400001,$C14<=8000000),ROUND(($C14-2400001)*0.28,0)+0+26400+117600+384000, IF($C14>=8000001,ROUND(($C14-8000001)*0.32,0)+0+26400+117600+384000+1568000, 0)))))),0)) -> 49429
A16: RICF | B16: Retenue | C16: =IF($B$4="Stagiaire",0, ROUND( IF($B$8=1,0, IF($B$8=1.5,5500, IF($B$8=2,11000, IF($B$8=2.5,16500, IF($B$8=3,22000, IF($B$8=3.5,27500, IF($B$8=4,33000, IF($B$8=4.5,38500, IF($B$8=5,44000, 0))))))))),0)) -> 22000
A17: ITS après RICF | B17: Retenue | C17: =IF($C$15-$C$16<0,0,$C$15-$C$16) -> 27429
A18: Contribution Employeur | B18: Retenue | D18: =IF(OR($B$4="Stagiaire",$B$5="Oui",,$B$5=""),0, ROUND($C$14*0.092,0)) -> 0
A19: Contribution Nationale | B19: Retenue | D19: =IF($B$4="Stagiaire",0, ROUND($C$14*0.012,0)) -> 4196
A20: Taxe d'apprentissage | B20: Retenue | D20: =IF($B$4="Stagiaire",0, ROUND($C$14*0.004,0)) -> 1399
A21: FDFP TFPC | B21: Retenue | D21: =IF($B$4="Stagiaire",0, ROUND($C$14*0.012,0)) -> 4196
A22: FDFP Regul | B22: Retenue | D22: =0 -> 0 | F22: Données CIFIDEC
A23: CNPS salarié | B23: Retenue | C23: =IF($B$4="Stagiaire",0, ROUND( IF($C$14<75000,75000*0.063, IF(AND($C$14>=75000,$C$14<=3375000),$C$14*0.063, IF($C$14>3375000,3375000*0.063,0))), 0)) -> 22029 | G23: =C23-ROUND(F23,0) -> 22029
A24: CNPS employeur | B24: Retenue | D24: =IF($B$4="Stagiaire",0, ROUND( IF($C$14<75000,75000*0.077, IF(AND($C$14>=75000,$C$14<=3375000),$C$14*0.077, IF($C$14>3375000,3375000*0.077,0))), 0)) -> 26924 | G24: =D24-ROUND(F24,0) -> 26924
A25: Prestations familiales | B25: Retenue | D25: =IF($B$4="Stagiaire",0, ROUND( IF($C$14<75000,75000*0.05, IF($C$14>=75000,75000*0.05, IF($C$14>3375000,75000*0.05,0))), 0)) -> 3750
A26: Assurance maternité | B26: Retenue | D26: =IF($B$4="Stagiaire",0, ROUND( IF($C$14<75000,75000*0.0075, IF($C$14>=75000,75000*0.0075, IF($C$14>3375000,75000*0.0075,0))), 2)) -> 562.5
A27: Accident de travail | B27: Retenue | D27: =IF($B$4="Stagiaire",0, ROUND( IF($C$14<75000,75000*0.05, IF($C$14>=75000,75000*0.05, IF($C$14>3375000,75000*0.05,0))), 0)) -> 3750
A28: CMU salarié | B28: Retenue | C28: =IF($B$6="C",ROUND(IF($B$9="Total",0,($B$7+1)*500),0),ROUND(IF($B$9="Total",0,($B$7+2)*500),0)) -> 2000
A29: CMU employeur | B29: Retenue | D29: =C28 -> 2000
A30: Indemnité de transport | B30: Gain | C30: =30000 -> 30000
A31: Net à payer | B31: Gain | C31: =IF($B$4="Stagiaire",$C$30, C14-C17-C23-C28+C30) -> 328206
A32: Charges salariales | C32: =C17+C23+C28 -> 51458
A33: Charges patronales | D33: =D18+D20+D21+D22+D24+D25+D26+D27+D29 -> 42581.5

Sheet ASSI BONAVENTURE
A1: CALCULATEUR DE SALAIRE BRUT | F1: Synthèse
A3: Salarié | B3: ASSI BONAVENTURE
A4: Statut | B4: Employé
A5: Local | B5: Oui
A6: Situation | B6: C
A7: Nb Enfants | B7: 0
A8: Parts | B8: =IF(IF($B$4="Stagiaire",0,IF(AND($B$6 = "C", $B$7 = 0), 1,IF(AND($B$6 = "C", $B$7 = 1), 2,IF(AND($B$6 = "C", $B$7 = 2), 2.5,IF(AND($B$6 = "C", $B$7 = 3), 3,IF(AND($B$6 = "C", $B$7 = 4), 3.5,IF(AND($B$6 = "C", $B$7 = 5), 4,IF(AND($B$6 = "C", $B$7 = 6), 4.5,IF(AND($B$6 = "M", $B$7 = 0), 2,IF(AND($B$6 = "M", $B$7 = 1), 2.5,IF(AND($B$6 = "M", $B$7 = 2), 3,IF(AND($B$6 = "M", $B$7 = 3), 3.5,IF(AND($B$6 = "M", $B$7 = 4), 4,IF(AND($B$6 = "M", $B$7 = 5), 4.5,IF(AND($B$6 = "M", $B$7 = 6), 5,"")))))))))))))))<=5,IF($B$4="Stagiaire",0,IF(AND($B$6 = "C", $B$7 = 0), 1,IF(AND($B$6 = "C", $B$7 = 1), 2,IF(AND($B$6 = "C", $B$7 = 2), 2.5,IF(AND($B$6 = "C", $B$7 = 3), 3,IF(AND($B$6 = "C", $B$7 = 4), 3.5,IF(AND($B$6 = "C", $B$7 = 5), 4,IF(AND($B$6 = "C", $B$7 = 6), 4.5,IF(AND($B$6 = "M", $B$7 = 0), 2,IF(AND($B$6 = "M", $B$7 = 1), 2.5,IF(AND($B$6 = "M", $B$7 = 2), 3,IF(AND($B$6 = "M", $B$7 = 3), 3.5,IF(AND($B$6 = "M", $B$7 = 4), 4,IF(AND($B$6 = "M", $B$7 = 5), 4.5,IF(AND($B$6 = "M", $B$7 = 6), 5,""))))))))))))))),5) -> 1
A9: Charge CMU | B9: Partiel
A11: Rubrique | B11: Type | C11: Montant salarié | D11: Montant employeur
A12: Salaire catégoriel | B12: Gain
A13: Sursalaire | B13: Gain
A14: Salaire brut | B14: Gain | C14: 215375
A15: ITS avant RICF | B15: Retenue | C15: =IF($B$4="Stagiaire",0, ROUND( IF(AND($C14=0,$C14<=75000),0, IF(AND($C14>=75001,$C14<=240000),ROUND(($C14-75001)*0.16,0)+0, IF(AND($C14>=240001,$C14<=800000),ROUND(($C14-240001)*0.21,0)+0+26400, IF(AND($C14>=800001,$C14<=2400000),ROUND(($C14-800001)*0.24,0)+0+26400+117600, IF(AND($C14>=2400001,$C14<=8000000),ROUND(($C14-2400001)*0.28,0)+0+26400+117600+384000, IF($C14>=8000001,ROUND(($C14-8000001)*0.32,0)+0+26400+117600+384000+1568000, 0)))))),0)) -> 22460
A16: RICF | B16: Retenue | C16: =IF($B$4="Stagiaire",0, ROUND( IF($B$8=1,0, IF($B$8=1.5,5500, IF($B$8=2,11000, IF($B$8=2.5,16500, IF($B$8=3,22000, IF($B$8=3.5,27500, IF($B$8=4,33000, IF($B$8=4.5,38500, IF($B$8=5,44000, 0))))))))),0)) -> 0
A17: ITS après RICF | B17: Retenue | C17: =IF($C$15-$C$16<0,0,$C$15-$C$16) -> 22460
A18: Contribution Employeur | B18: Retenue | D18: =IF(OR($B$4="Stagiaire",$B$5="Oui",,$B$5=""),0, ROUND($C$14*0.092,0)) -> 0
A19: Contribution Nationale | B19: Retenue | D19: =IF($B$4="Stagiaire",0, ROUND($C$14*0.012,0)) -> 2585
A20: Taxe d'apprentissage | B20: Retenue | D20: =IF($B$4="Stagiaire",0, ROUND($C$14*0.004,0)) -> 862
A21: FDFP TFPC | B21: Retenue | D21: =IF($B$4="Stagiaire",0, ROUND($C$14*0.012,0)) -> 2585
A22: FDFP Regul | B22: Retenue | D22: =0 -> 0 | F22: Données CIFIDEC
A23: CNPS salarié | B23: Retenue | C23: =IF($B$4="Stagiaire",0, ROUND( IF($C$14<75000,75000*0.063, IF(AND($C$14>=75000,$C$14<=3375000),$C$14*0.063, IF($C$14>3375000,3375000*0.063,0))), 0)) -> 13569 | G23: =C23-ROUND(F23,0) -> 13569
A24: CNPS employeur | B24: Retenue | D24: =IF($B$4="Stagiaire",0, ROUND( IF($C$14<75000,75000*0.077, IF(AND($C$14>=75000,$C$14<=3375000),$C$14*0.077, IF($C$14>3375000,3375000*0.077,0))), 0)) -> 16584 | G24: =D24-ROUND(F24,0) -> 16584
A25: Prestations familiales | B25: Retenue | D25: =IF($B$4="Stagiaire",0, ROUND( IF($C$14<75000,75000*0.05, IF($C$14>=75000,75000*0.05, IF($C$14>3375000,75000*0.05,0))), 0)) -> 3750
A26: Assurance maternité | B26: Retenue | D26: =IF($B$4="Stagiaire",0, ROUND( IF($C$14<75000,75000*0.0075, IF($C$14>=75000,75000*0.0075, IF($C$14>3375000,75000*0.0075,0))), 2)) -> 562.5
A27: Accident de travail | B27: Retenue | D27: =IF($B$4="Stagiaire",0, ROUND( IF($C$14<75000,75000*0.05, IF($C$14>=75000,75000*0.05, IF($C$14>3375000,75000*0.05,0))), 0)) -> 3750
A28: CMU salarié | B28: Retenue | C28: =IF($B$6="C",ROUND(IF($B$9="Total",0,($B$7+1)*500),0),ROUND(IF($B$9="Total",0,($B$7+2)*500),0)) -> 500
A29: CMU employeur | B29: Retenue | D29: =C28 -> 500
A30: Indemnité de transport | B30: Gain | C30: =30000 -> 30000
A31: Net à payer | B31: Gain | C31: =IF($B$4="Stagiaire",$C$30, C14-C17-C23-C28+C30) -> 208846
A32: Charges salariales | C32: =C17+C23+C28 -> 36529
A33: Charges patronales | D33: =D18+D20+D21+D22+D24+D25+D26+D27+D29 -> 28593.5

Sheet BESONGLACHE PAUL
A1: CALCULATEUR DE SALAIRE BRUT | F1: Synthèse
A3: Salarié | B3: BESONGACHE PAUL
A4: Statut | B4: Employé
A5: Local | B5: Non
A6: Situation | B6: M
A7: Nb Enfants | B7: 2
A8: Parts | B8: =IF(IF($B$4="Stagiaire",0,IF(AND($B$6 = "C", $B$7 = 0), 1,IF(AND($B$6 = "C", $B$7 = 1), 2,IF(AND($B$6 = "C", $B$7 = 2), 2.5,IF(AND($B$6 = "C", $B$7 = 3), 3,IF(AND($B$6 = "C", $B$7 = 4), 3.5,IF(AND($B$6 = "C", $B$7 = 5), 4,IF(AND($B$6 = "C", $B$7 = 6), 4.5,IF(AND($B$6 = "M", $B$7 = 0), 2,IF(AND($B$6 = "M", $B$7 = 1), 2.5,IF(AND($B$6 = "M", $B$7 = 2), 3,IF(AND($B$6 = "M", $B$7 = 3), 3.5,IF(AND($B$6 = "M", $B$7 = 4), 4,IF(AND($B$6 = "M", $B$7 = 5), 4.5,IF(AND($B$6 = "M", $B$7 = 6), 5,"")))))))))))))))<=5,IF($B$4="Stagiaire",0,IF(AND($B$6 = "C", $B$7 = 0), 1,IF(AND($B$6 = "C", $B$7 = 1), 2,IF(AND($B$6 = "C", $B$7 = 2), 2.5,IF(AND($B$6 = "C", $B$7 = 3), 3,IF(AND($B$6 = "C", $B$7 = 4), 3.5,IF(AND($B$6 = "C", $B$7 = 5), 4,IF(AND($B$6 = "C", $B$7 = 6), 4.5,IF(AND($B$6 = "M", $B$7 = 0), 2,IF(AND($B$6 = "M", $B$7 = 1), 2.5,IF(AND($B$6 = "M", $B$7 = 2), 3,IF(AND($B$6 = "M", $B$7 = 3), 3.5,IF(AND($B$6 = "M", $B$7 = 4), 4,IF(AND($B$6 = "M", $B$7 = 5), 4.5,IF(AND($B$6 = "M", $B$7 = 6), 5,""))))))))))))))),5) -> 3
A9: Charge CMU | B9: Partiel
A11: Rubrique | B11: Type | C11: Montant salarié | D11: Montant employeur
A12: Salaire catégoriel | B12: Gain
A13: Sursalaire | B13: Gain
A14: Salaire brut | B14: Gain | C14: 5781400
A15: ITS avant RICF | B15: Retenue | C15: =IF($B$4="Stagiaire",0, ROUND( IF(AND($C14=0,$C14<=75000),0, IF(AND($C14>=75001,$C14<=240000),ROUND(($C14-75001)*0.16,0)+0, IF(AND($C14>=240001,$C14<=800000),ROUND(($C14-240001)*0.21,0)+0+26400, IF(AND($C14>=800001,$C14<=2400000),ROUND(($C14-800001)*0.24,0)+0+26400+117600, IF(AND($C14>=2400001,$C14<=8000000),ROUND(($C14-2400001)*0.28,0)+0+26400+117600+384000, IF($C14>=8000001,ROUND(($C14-8000001)*0.32,0)+0+26400+117600+384000+1568000, 0)))))),0)) -> 1474792
A16: RICF | B16: Retenue | C16: =IF($B$4="Stagiaire",0, ROUND( IF($B$8=1,0, IF($B$8=1.5,5500, IF($B$8=2,11000, IF($B$8=2.5,16500, IF($B$8=3,22000, IF($B$8=3.5,27500, IF($B$8=4,33000, IF($B$8=4.5,38500, IF($B$8=5,44000, 0))))))))),0)) -> 22000
A17: ITS après RICF | B17: Retenue | C17: =IF($C$15-$C$16<0,0,$C$15-$C$16) -> 1452792
A18: Contribution Employeur | B18: Retenue | D18: =IF(OR($B$4="Stagiaire",$B$5="Oui",,$B$5=""),0, ROUND($C$14*0.092,0)) -> 531889
A19: Contribution Nationale | B19: Retenue | D19: =IF($B$4="Stagiaire",0, ROUND($C$14*0.012,0)) -> 69377
A20: Taxe d'apprentissage | B20: Retenue | D20: =IF($B$4="Stagiaire",0, ROUND($C$14*0.004,0)) -> 23126
A21: FDFP TFPC | B21: Retenue | D21: =IF($B$4="Stagiaire",0, ROUND($C$14*0.012,0)) -> 69377
A22: FDFP Regul | B22: Retenue | D22: =0 -> 0 | F22: Données CIFIDEC
